Workbook

Sheet Final Summary
A1: Main Benchmark
A2: Total Issues: 225 | B2: Total F2P: 75
A4: By Models
A5: Model: gpt-4.1-mini
A7: No. | B7: Pipeline | C7: F2P App (w/ in-Patch) | D7: F2P App (w/o in-patch) | E7: F2P App | F7: F2P Framework (w/ in-Patch) | G7: F2P Framework (w/o in-patch) | H7: F2P Framework | I7: Total F2P (w/ in-patch) | J7: Total F2P (w/o in-patch) | K7: Total F2P | L7: Avg. Duration | M7: Avg. Cost | N7: Avg. Token Consumption | O7: Env. build | P7: Avg. Input Token | Q7: Avg. Output Token
A8: 1 | B8: AgentBug-Smith | C8: =3+0+0+0 -> 3 | D8: =6+3+4+0 -> 13 | E8: =C8+D8 -> 16 | F8: =6+1+14+0 -> 21 | G8: =4+0+2+2 -> 8 | H8: =F8+G8 -> 29 | I8: =C8+F8 -> 24 | J8: =D8+G8 -> 21 | K8: =I8+J8 -> 45 | L8: 58m 10s | M8: =((P8/1000000)*0.4)+((Q8/1000000)*1.6) -> 0.5595124 | N8: =P8+Q8 -> 1287247 | O8: 84 | P8: 1250069 | Q8: 37178
A9: 2 | B9: SWE-Factory | C9: =3+0+0+0 -> 3 | D9: 0 | E9: =C9+D9 -> 3 | F9: =8+0+10+0 -> 18 | G9: 0 | H9: =F9+G9 -> 18 | I9: =C9+F9 -> 21 | J9: =D9+G9 -> 0 | K9: =I9+J9 -> 21 | L9: 5m 45s | M9: =((P9/1000000)*0.4)+((Q9/1000000)*1.6) -> 0.0906424 | N9: =P9+Q9 -> 167176 | O9: 36 | P9: 147366 | Q9: 19810
A10: 3 | B10: SWE-bench-Live | C10: =1+0+0+0 -> 1 | D10: 0 | E10: =C10+D10 -> 1 | F10: =3+1+1+0 -> 5 | G10: 0 | H10: =F10+G10 -> 5 | I10: =C10+F10 -> 6 | J10: =D10+G10 -> 0 | K10: =I10+J10 -> 6 | L10: 22m 19s | M10: =((P10/1000000)*0.4)+((Q10/1000000)*1.6) -> 0.4091236 | N10: =P10+Q10 -> 1007209 | O10: 33 | P10: 1002009 | Q10: 5200
A12: Model: Deepseek-v3.2
A14: No. | B14: Pipeline | C14: F2P App (w/ in-Patch) | D14: F2P App (w/o in-patch) | E14: F2P App | F14: F2P Framework (w/ in-Patch) | G14: F2P Framework (w/o in-patch) | H14: F2P Framework | I14: Total F2P (w/ in-patch) | J14: Total F2P (w/o in-patch) | K14: Total F2P | L14: Avg. Duration | M14: Avg. Cost | N14: Avg. Token Consumption | O14: Env. build | P14: Avg. Input Token | Q14: Avg. Output Token
A15: 1 | B15: AgentBug-Smith | C15: 5 | D15: 21 | E15: =C15+D15 -> 26 | F15: 29 | G15: 8 | H15: =F15+G15 -> 37 | I15: =F15+C15 -> 34 | J15: =G15+D15 -> 29 | K15: =I15+J15 -> 63 | L15: 76m 26s | M15: =((P15/1000000)*0.28)+((Q15/1000000)*0.4) -> 2.4390618 | N15: =P15+Q15 -> 8667177 | O15: 93 | P15: 8565075 | Q15: 102102
A16: 2 | B16: SWE-Factory | C16: 3 | D16: 0 | E16: =C16+D16 -> 3 | F16: 28 | G16: 0 | H16: =F16+G16 -> 28 | I16: =F16+C16 -> 31 | J16: =G16+D16 -> 0 | K16: =I16+J16 -> 31 | L16: 6m 27s | M16: =((P16/1000000)*0.28)+((Q16/1000000)*0.4) -> 0.30701028 | N16: =P16+Q16 -> 1039926 | O16: 44 | P16: 908001 | Q16: 131925
A17: 3 | B17: SWE-bench-Live | C17: 0 | D17: 0 | E17: =C17+D17 -> 0 | F17: 1 | G17: 0 | H17: =F17+G17 -> 1 | I17: =F17+C17 -> 1 | J17: =G17+D17 -> 0 | K17: =I17+J17 -> 1 | L17: 17m 22s | M17: =((P17/1000000)*0.28)+((Q17/1000000)*0.4) -> 1.0495557 | N17: =P17+Q17 -> 3738206 | O17: 14 | P17: 3714389 | Q17: 23817
A19: Model: Kimi-k2.5
A21: No. | B21: Pipeline | C21: F2P App (w/ in-Patch) | D21: F2P App (w/o in-patch) | E21: F2P App | F21: F2P Framework (w/ in-Patch) | G21: F2P Framework (w/o in-patch) | H21: F2P Framework | I21: Total F2P (w/ in-patch) | J21: Total F2P (w/o in-patch) | K21: Total F2P | L21: Avg. Duration | M21: Avg. Cost | N21: Avg. Token Consumption | O21: Env. build | P21: Avg. Input Token | Q21: Avg. Output Token
A22: 1 | B22: AgentBug-Smith | C22: 3 | D22: 22 | E22: =C22+D22 -> 25 | F22: 17 | G22: 4 | H22: =F22+G22 -> 21 | I22: =C22+F22 -> 20 | J22: =D22+G22 -> 26 | K22: =J22+I22 -> 46 | L22: 57m 15s | M22: =((P22/1000000)*0.6)+((Q22/1000000)*3) -> 0.9140562 | N22: =P22+Q22 -> 1285523 | O22: 53 | P22: 1226047 | Q22: 59476
A23: 2 | B23: SWE-Factory | C23: 2 | D23: 0 | E23: =C23+D23 -> 2 | F23: 17 | G23: 0 | H23: =F23+G23 -> 17 | I23: =C23+F23 -> 19 | J23: =D23+G23 -> 0 | K23: =J23+I23 -> 19 | L23: 4m 48s | M23: =((P23/1000000)*0.6)+((Q23/1000000)*3) -> 0.365214 | N23: =P23+Q23 -> 592602 | O23: 27 | P23: 588580 | Q23: 4022
A24: 3 | B24: SWE-bench-Live | C24: 2 | D24: 0 | E24: =C24+D24 -> 2 | F24: 4 | G24: 0 | H24: =F24+G24 -> 4 | I24: =C24+F24 -> 6 | J24: =D24+G24 -> 0 | K24: =J24+I24 -> 6 | L24: 25m 14s | M24: =((P24/1000000)*0.6)+((Q24/1000000)*3) -> 0.6554874 | N24: =P24+Q24 -> 1065259 | O24: 29 | P24: 1058454 | Q24: 6805
A28: Repository Distribution
A30: Agent Frameworks | B30: Agent Applications
A31: No. | B31: Repository | C31: Link | D31: Stars | E31: License | F31: Total Issues with In-Patch Test | G31: Total Issues without In-Patch Test | H31: Total Issues | I31: Total F2P
I32: GPT-4.1-Mini | J32: Deepseek-v3.2 | K32: Kimi-k2.5
A33: 1 | B33: dapr/dapr-agents | C33: https://github.com/dapr/dapr-agents/ | D33: 743 | E33: Apache-2.0 license | F33: 1 | G33: 2 | H33: 3 | I33: 1 | J33: 2 | K33: 2
A34: 2 | B34: VoltAgent/voltagent | C34: https://github.com/VoltAgent/voltagent/ | D34: 7.1k | E34: MIT license | F34: 0 | G34: 1 | H34: 1 | I34: 0 | J34: 0 | K34: 0
A35: 3 | B35: agentscope-ai/agentscope | C35: https://github.com/agentscope-ai/agentscope/ | D35: 22.5k | E35: Apache-2.0 license | F35: 10 | G35: 19 | H35: 29 | I35: 15 | J35: 15 | K35: 10
A36: 4 | B36: crewAIInc/crewAI | C36: https://github.com/crewAIInc/crewAI | D36: 47.6k | E36: MIT license | F36: 28 | G36: 21 | H36: 49 | I36: 12 | J36: 15 | K36: 4
A37: 5 | B37: strands-agents/harness-sdk | C37: https://github.com/strands-agents/sdk-python | D37: 5.5k | E37: Apache-2.0 license | F37: 1 | G37: 0 | H37: 1 | I37: 1 | J37: 0 | K37: 1
A38: 6 | B38: mastra-ai/mastra | C38: https://github.com/mastra-ai/mastra | D38: 22.5k | E38: Apache-2.0 license | F38: 0 | G38: 3 | H38: 3 | I38: 0 | J38: 0 | K38: 0
A39: 7 | B39: langchain-ai/langgraph | C39: https://github.com/langchain-ai/langgraph | D39: 28.4k | E39: MIT license | F39: 11 | G39: 2 | H39: 13 | I39: 0 | J39: 5 | K39: 4
A40: 8 | B40: langflow-ai/langflow | C40: https://github.com/langflow-ai/langflow | D40: 148k | E40: MIT license | F40: 9 | G40: 2 | H40: 11 | I40: 0 | J40: 0 | K40: 0
A41: 9 | B41: geekan/MetaGPT | C41: https://github.com/geekan/MetaGPT | D41: 67.9k | E41: MIT license | F41: 7 | G41: 5 | H41: 12 | I41: 0 | J41: 0 | K41: 0
A42: 10 | B42: tensorzero/tensorzero | C42: https://github.com/tensorzero/tensorzero | D42: 11.4k | E42: Apache-2.0 license | F42: 11 | G42: 0 | H42: 11 | I42: 0 | J42: 0 | K42: 0
A43: 11 | B43: Significant-Gravitas/AutoGPT | C43: https://github.com/Significant-Gravitas/AutoGPT | D43: 183k | E43: MIT License & PolyForm Shield License 1.0.0 | F43: 10 | G43: 3 | H43: 13 | I43: 0 | J43: 2 | K43: 0
A44: 12 | B44: MLSysOps/MLE-agent | C44: https://github.com/MLSysOps/MLE-agent/ | D44: 1.5k | E44: MIT license | F44: 0 | G44: 21 | H44: 21 | I44: 6 | J44: 9 | K44: 10
A45: 13 | B45: always-further/AgentUp | C45: https://github.com/always-further/AgentUp/ | D45: 126 | E45: Apache-2.0 license | F45: 0 | G45: 2 | H45: 2 | I45: 0 | J45: 0 | K45: 0
A46: 14 | B46: Canner/WrenAI | C46: https://github.com/Canner/WrenAI | D46: 14.9k | E46: AGPL-3.0 license | F46: 0 | G46: 1 | H46: 1 | I46: 0 | J46: 0 | K46: 0
A47: 15 | B47: reworkd/AgentGPT | C47: https://github.com/reworkd/AgentGPT | D47: 35.9k | E47: GPL-3.0 license | F47: 1 | G47: 4 | H47: 5 | I47: 0 | J47: 0 | K47: 0
A48: 16 | B48: Aider-AI/aider | C48: https://github.com/Aider-AI/aider | D48: 42.8k | E48: Apache-2.0 license | F48: 1 | G48: 6 | H48: 7 | I48: 5 | J48: 7 | K48: 5
A49: 17 | B49: ValueCell-ai/valuecell | C49: https://github.com/ValueCell-ai/valuecell | D49: 10.2k | E49: Apache-2.0 license | F49: 0 | G49: 5 | H49: 5 | I49: 0 | J49: 0 | K49: 0
A50: 18 | B50: AntonOsika/gpt-engineer | C50: https://github.com/AntonOsika/gpt-engineer | D50: 55.2k | E50: MIT license | F50: 9 | G50: 10 | H50: 19 | I50: 5 | J50: 7 | K50: 9
...

Sheet RQ2
A1: issue_number | B1: url | C1: Alfin | D1: Yiming | E1: Human Golden | J1: issue_number | K1: url | L1: Alfin | M1: Yiming | N1: Human Golden | Q1: Yes | R1: No
A2: 1020 | B2: https://github.com/EaminC/AgentBug-Smith/tree/main/results/all_combined_f2p/issue_1020_20260814T120504Z | C2: Y | D2: Y | E2: Y | J2: 1037 | K2: https://github.com/EaminC/AgentBug-Smith/blob/main/data/issues_80/issue_1037.json | L2: Y | M2: Y | N2: Y | P2: Alfin | Q2: =COUNTIF(L2:L133, "Y") -> 123 | R2: =COUNTIF(L2:L133, "N") -> 9
A3: 1067 | B3: https://github.com/EaminC/AgentBug-Smith/tree/main/results/all_combined_f2p/issue_1067_20260814T123127Z | C3: Y | D3: Y | E3: Y | J3: 109 | K3: https://github.com/EaminC/AgentBug-Smith/blob/main/data/issues_80/issue_109.json | L3: Y | M3: Y | N3: Y | P3: Yiming | Q3: =COUNTIF(M2:M133, "Y") -> 123 | R3: =COUNTIF(M2:M133, "N") -> 9
A4: 1112 | B4: https://github.com/EaminC/AgentBug-Smith/tree/main/results/all_combined_f2p/issue_1112_20260623T030619Z | C4: Y | D4: Y | E4: Y | J4: 1129 | K4: https://github.com/EaminC/AgentBug-Smith/blob/main/data/issues_80/issue_1129.json | L4: Y | M4: Y | N4: Y | P4: Human Golden | Q4: =COUNTIF(N2:N133, "Y") -> 123 | R4: =COUNTIF(N2:N133, "N") -> 9
A5: 1115 | B5: https://github.com/EaminC/AgentBug-Smith/tree/main/results/all_combined_f2p/issue_1115_20260707T180736Z | C5: Y | D5: Y | E5: Y | J5: 1136 | K5: https://github.com/EaminC/AgentBug-Smith/blob/main/data/issues_80/issue_1136.json | L5: Y | M5: Y | N5: Y
A6: 1131 | B6: https://github.com/EaminC/AgentBug-Smith/tree/main/results/all_combined_f2p/issue_1131_20260814T215507Z | C6: Y | D6: Y | E6: Y | J6: 1197 | K6: https://github.com/EaminC/AgentBug-Smith/blob/main/data/issues_80/issue_1197.json | L6: Y | M6: Y | N6: Y | P6: Total labelled issues | Q6: 132
A7: 1136 | B7: https://github.com/EaminC/AgentBug-Smith/tree/main/results/all_combined_f2p/issue_1136_20260511T024303Z | C7: Y | D7: Y | E7: Y | J7: 121 | K7: https://github.com/EaminC/AgentBug-Smith/blob/main/data/issues_80/issue_121.json | L7: Y | M7: Y | N7: Y
A8: 1158 | B8: https://github.com/EaminC/AgentBug-Smith/tree/main/results/all_combined_f2p/issue_1158_20260814T222448Z | C8: Y | D8: Y | E8: Y | J8: 1222 | K8: https://github.com/EaminC/AgentBug-Smith/blob/main/data/issues_80/issue_1222.json | L8: Y | M8: Y | N8: Y | P8: Observed agreement | Q8: =Q4/132 -> 0.93181818
A9: 1176 | B9: https://github.com/EaminC/AgentBug-Smith/tree/main/results/all_combined_f2p/issue_1176_20260815T110931Z | C9: Y | D9: Y | E9: Y | J9: 1277 | K9: https://github.com/EaminC/AgentBug-Smith/blob/main/data/issues_80/issue_1277.json | L9: Y | M9: Y | N9: Y
A10: 1197 | B10: https://github.com/EaminC/AgentBug-Smith/tree/main/results/all_combined_f2p/issue_1197_20260815T160749Z | C10: Y | D10: Y | E10: Y | J10: 1280 | K10: https://github.com/EaminC/AgentBug-Smith/blob/main/data/issues_80/issue_1280.json | L10: Y | M10: Y | N10: Y | Q10: Alfiin: Yes | R10: Alfin: No
A11: 1208 | B11: https://github.com/EaminC/AgentBug-Smith/tree/main/results/all_combined_f2p/issue_1208_20260816T000846Z | C11: Y | D11: Y | E11: Y | J11: 137 | K11: https://github.com/EaminC/AgentBug-Smith/blob/main/data/issues_80/issue_137.json | L11: Y | M11: Y | N11: Y | P11: Yiming: Yes | Q11: =COUNTIFS(L2:L133,"Y",M2:M133,"Y") -> 122 | R11: =COUNTIFS(L2:L133,"N",M2:M133,"Y") -> 1
A12: 121 | B12: https://github.com/EaminC/AgentBug-Smith/tree/main/results/all_combined_f2p/issue_121_20260614T144239Z | C12: Y | D12: Y | E12: Y | J12: 1437 | K12: https://github.com/EaminC/AgentBug-Smith/blob/main/data/issues_80/issue_1437.json | L12: Y | M12: Y | N12: Y | P12: Yiming: No | Q12: =COUNTIFS(M2:M133,"N",L2:L133,"Y") -> 1 | R12: =COUNTIFS(M2:M133,"N",L2:L133,"N") -> 8
A13: 1221 | B13: https://github.com/EaminC/AgentBug-Smith/tree/main/results/all_combined_f2p/issue_1221_20260816T090307Z | C13: Y | D13: Y | E13: Y | J13: 1439 | K13: https://github.com/EaminC/AgentBug-Smith/blob/main/data/issues_80/issue_1439.json | L13: Y | M13: Y | N13: Y
A14: 1222 | B14: https://github.com/EaminC/AgentBug-Smith/tree/main/results/all_combined_f2p/issue_1222_20260617T122512Z | C14: Y | D14: Y | E14: Y | J14: 1445 | K14: https://github.com/EaminC/AgentBug-Smith/blob/main/data/issues_80/issue_1445.json | L14: Y | M14: Y | N14: Y | P14: Observed agreement | Q14: =(Q11+R12)/Q6 -> 0.98484848
A15: 1260 | B15: https://github.com/EaminC/AgentBug-Smith/tree/main/results/all_combined_f2p/issue_1260_20260816T160950Z | C15: Y | D15: Y | E15: Y | J15: 1455 | K15: https://github.com/EaminC/AgentBug-Smith/blob/main/data/issues_80/issue_1455.json | L15: Y | M15: Y | N15: Y | P15: Alfin Yes proportion | Q15: =Q2/Q6 -> 0.93181818 | R15: Alfin No proportion | S15: =R2/Q6 -> 0.068181818
A16: 1272 | B16: https://github.com/EaminC/AgentBug-Smith/tree/main/results/all_combined_f2p/issue_1272_20260816T174203Z | C16: Y | D16: Y | E16: Y | J16: 149 | K16: https://github.com/EaminC/AgentBug-Smith/blob/main/data/issues_80/issue_149.json | L16: Y | M16: Y | N16: Y | P16: Yiming Yes proportion | Q16: =Q3/Q6 -> 0.93181818 | R16: Yiming No proportion | S16: =R3/Q6 -> 0.068181818
A17: 1277 | B17: https://github.com/EaminC/AgentBug-Smith/tree/main/results/all_combined_f2p/issue_1277_20260511T034601Z | C17: Y | D17: Y | E17: Y | J17: 1511 | K17: https://github.com/EaminC/AgentBug-Smith/blob/main/data/issues_80/issue_1511.json | L17: Y | M17: Y | N17: Y | P17: Expected agreement | Q17: =(Q15*Q16)+(S15*S16) -> 0.87293388
A18: 1280 | B18: https://github.com/EaminC/AgentBug-Smith/tree/main/results/all_combined_f2p/issue_1280_20260717T161006Z | C18: Y | D18: Y | E18: Y | J18: 1583 | K18: https://github.com/EaminC/AgentBug-Smith/blob/main/data/issues_80/issue_1583.json | L18: Y | M18: Y | N18: Y
A19: 1294 | B19: https://github.com/EaminC/AgentBug-Smith/tree/main/results/all_combined_f2p/issue_1294_20260816T182750Z | C19: Y | D19: Y | E19: Y | J19: 1675 | K19: https://github.com/EaminC/AgentBug-Smith/blob/main/data/issues_80/issue_1675.json | L19: Y | M19: Y | N19: Y | P19: Cohen's Kappa | Q19: =(Q14-Q17)/(1-Q17) -> 0.88075881
A20: 1297 | B20: https://github.com/EaminC/AgentBug-Smith/tree/main/results/all_combined_f2p/issue_1297_20260624T043153Z | C20: Y | D20: Y | E20: Y | J20: 169 | K20: https://github.com/EaminC/AgentBug-Smith/blob/main/data/issues_80/issue_169.json | L20: Y | M20: Y | N20: Y
A21: 1334 | B21: https://github.com/EaminC/AgentBug-Smith/tree/main/results/all_combined_f2p/issue_1334_20260816T182942Z | C21: Y | D21: Y | E21: Y | J21: 174 | K21: https://github.com/EaminC/AgentBug-Smith/blob/main/data/issues_80/issue_174.json | L21: Y | M21: Y | N21: Y
A22: 1351 | B22: https://github.com/EaminC/AgentBug-Smith/tree/main/results/all_combined_f2p/issue_1351_20260624T075019Z | C22: Y | D22: Y | E22: Y | J22: 177 | K22: https://github.com/EaminC/AgentBug-Smith/blob/main/data/issues_80/issue_177.json | L22: Y | M22: Y | N22: Y
A23: 141 | B23: https://github.com/EaminC/AgentBug-Smith/tree/main/results/all_combined_f2p/issue_141_20260729T075605Z | C23: Y | D23: Y | E23: Y | J23: 1851 | K23: https://github.com/EaminC/AgentBug-Smith/blob/main/data/issues_80/issue_1851.json | L23: Y | M23: Y | N23: Y
A24: 1432 | B24: https://github.com/EaminC/AgentBug-Smith/tree/main/results/all_combined_f2p/issue_1432_20260817T045516Z | C24: Y | D24: Y | E24: Y | J24: 1886 | K24: https://github.com/EaminC/AgentBug-Smith/blob/main/data/issues_80/issue_1886.json | L24: Y | M24: Y | N24: Y
A25: 1439 | B25: https://github.com/EaminC/AgentBug-Smith/tree/main/results/all_combined_f2p/issue_1439_20260802T002117Z | C25: Y | D25: Y | E25: Y | J25: 1887 | K25: https://github.com/EaminC/AgentBug-Smith/blob/main/data/issues_80/issue_1887.json | L25: N | M25: N | N25: N
A26: 1538 | B26: https://github.com/EaminC/AgentBug-Smith/tree/main/results/all_combined_f2p/issue_1538_20260817T110225Z | C26: Y | D26: Y | E26: Y | J26: 209 | K26: https://github.com/EaminC/AgentBug-Smith/blob/main/data/issues_80/issue_209.json | L26: Y | M26: Y | N26: Y
A27: 1545 | B27: https://github.com/EaminC/AgentBug-Smith/tree/main/results/all_combined_f2p/issue_1545_20260817T110601Z | C27: Y | D27: Y | E27: Y | J27: 2390 | K27: https://github.com/EaminC/AgentBug-Smith/blob/main/data/issues_80/issue_2390.json | L27: Y | M27: Y | N27: Y
A28: 1551 | B28: https://github.com/EaminC/AgentBug-Smith/tree/main/results/all_combined_f2p/issue_1551_20260817T114349Z | C28: Y | D28: Y | E28: Y | J28: 255 | K28: https://github.com/EaminC/AgentBug-Smith/blob/main/data/issues_80/issue_255.json | L28: Y | M28: Y | N28: Y
A29: 1651 | B29: https://github.com/EaminC/AgentBug-Smith/tree/main/results/all_combined_f2p/issue_1651_20260817T190549Z | C29: Y | D29: Y | E29: Y | J29: 256 | K29: https://github.com/EaminC/AgentBug-Smith/blob/main/data/issues_80/issue_256.json | L29: Y | M29: Y | N29: Y
A30: 166 | B30: https://github.com/EaminC/AgentBug-Smith/tree/main/results/all_combined_f2p/issue_166_20260703T205716Z | C30: Y | D30: Y | E30: Y | J30: 259 | K30: https://github.com/EaminC/AgentBug-Smith/blob/main/data/issues_80/issue_259.json | L30: Y | M30: Y | N30: Y
A31: 1675 | B31: https://github.com/EaminC/AgentBug-Smith/tree/main/results/all_combined_f2p/issue_1675_20260617T165705Z | C31: Y | D31: Y | E31: Y | J31: 273 | K31: https://github.com/EaminC/AgentBug-Smith/blob/main/data/issues_80/issue_273.json | L31: Y | M31: Y | N31: Y
... A59: 194 | B59: https://github.com/EaminC/AgentBug-Smith/tree/main/results/all_combined_f2p/issue_194_20260623T191609Z | C59: Y | D59: Y | E59: Y | J59: 6050 | K59: https://github.com/EaminC/AgentBug-Smith/blob/main/data/issues_80/issue_6050.json | L59: Y | M59: Y | N59: Y
A60: 196 | B60: https://github.com/EaminC/AgentBug-Smith/tree/main/results/all_combined_f2p/issue_196_20260629T055224Z | C60: N | D60: Y | E60: N | F60: The fix is in the example not the agent itself. Therefore, I don't think it is agent issue. | J60: 6072 | K60: https://github.com/EaminC/AgentBug-Smith/blob/main/data/issues_80/issue_6072.json | L60: Y | M60: Y | N60: Y
A61: 1965 | B61: https://github.com/EaminC/AgentBug-Smith/tree/main/results/all_combined_f2p/issue_1965_20260729T165449Z | C61: Y | D61: Y | E61: Y | J61: 6212 | K61: https://github.com/EaminC/AgentBug-Smith/blob/main/data/issues_80/issue_6212.json | L61: Y | M61: Y | N61: Y
A62: 2000 | B62: https://github.com/EaminC/AgentBug-Smith/tree/main/results/all_combined_f2p/issue_2000_20260808T192026Z | C62: Y | D62: Y | E62: Y | J62: 6302 | K62: https://github.com/EaminC/AgentBug-Smith/blob/main/data/issues_80/issue_6302.json | L62: Y | M62: Y | N62: Y
A63: 2007 | B63: https://github.com/EaminC/AgentBug-Smith/tree/main/results/all_combined_f2p/issue_2007_20260819T163823Z | C63: Y | D63: Y | E63: Y | J63: 6409 | K63: https://github.com/EaminC/AgentBug-Smith/blob/main/data/issues_80/issue_6409.json | L63: Y | M63: Y | N63: Y
A64: 2052 | B64: https://github.com/EaminC/AgentBug-Smith/tree/main/results/all_combined_f2p/issue_2052_20260729T231408Z | C64: Y | D64: Y | E64: Y | J64: 6465 | K64: https://github.com/EaminC/AgentBug-Smith/blob/main/data/issues_80/issue_6465.json | L64: Y | M64: Y | N64: Y
A65: 2055 | B65: https://github.com/EaminC/AgentBug-Smith/tree/main/results/all_combined_f2p/issue_2055_20260730T044249Z | C65: Y | D65: Y | E65: Y | J65: 6585 | K65: https://github.com/EaminC/AgentBug-Smith/blob/main/data/issues_80/issue_6585.json | L65: Y | M65: Y | N65: Y
A66: 2089 | B66: https://github.com/EaminC/AgentBug-Smith/tree/main/results/all_combined_f2p/issue_2089_20260823T001916Z | C66: Y | D66: Y | E66: Y | J66: 66 | K66: https://github.com/EaminC/AgentBug-Smith/blob/main/data/issues_80/issue_66.json | L66: Y | M66: Y | N66: Y
A67: 209 | B67: https://github.com/EaminC/AgentBug-Smith/tree/main/results/all_combined_f2p/issue_209_20260619T235044Z | C67: Y | D67: Y | E67: Y | J67: 682 | K67: https://github.com/EaminC/AgentBug-Smith/blob/main/data/issues_80/issue_682.json | L67: Y | M67: Y | N67: Y
...

Sheet RQ2（Eamin）
A1: issue_number | B1: url | C1: Alfin | D1: Yiming
A2: 3828 | B2: https://github.com/EaminC/AgentBug-Smith/tree/main/results/all_combined_f2p/issue_3828_20260525T192413Z | C2: Y | D2: Y
A3: 1297 | B3: https://github.com/EaminC/AgentBug-Smith/tree/main/results/all_combined_f2p/issue_1297_20260624T043153Z | C3: Y | D3: Y
A4: 1112 | B4: https://github.com/EaminC/AgentBug-Smith/tree/main/results/all_combined_f2p/issue_1112_20260623T030619Z | C4: Y | D4: Y
A5: 71 | B5: https://github.com/EaminC/AgentBug-Smith/tree/main/results/all_combined_f2p/issue_71_20260510T083954Z | C5: Y | D5: N
A6: 1765 | B6: https://github.com/EaminC/AgentBug-Smith/tree/main/results/all_combined_f2p/issue_1765_20260729T112754Z | C6: Y | D6: Y
A7: 1714 | B7: https://github.com/EaminC/AgentBug-Smith/tree/main/results/all_combined_f2p/issue_1714_20260818T071421Z | C7: Y | D7: Y
A8: 1702 | B8: https://github.com/EaminC/AgentBug-Smith/tree/main/results/all_combined_f2p/issue_1702_20260818T063539Z | C8: Y | D8: Y
A9: 1439 | B9: https://github.com/EaminC/AgentBug-Smith/tree/main/results/all_combined_f2p/issue_1439_20260802T002117Z | C9: Y | D9: Y
A10: 70 | B10: https://github.com/EaminC/AgentBug-Smith/tree/main/results/all_combined_f2p/issue_70_20260512T041132Z | C10: Y | D10: N
A11: 1280 | B11: https://github.com/EaminC/AgentBug-Smith/tree/main/results/all_combined_f2p/issue_1280_20260717T161006Z | C11: Y | D11: Y
A12: 529 | B12: https://github.com/EaminC/AgentBug-Smith/tree/main/results/all_combined_f2p/issue_529_20260813T191356Z | C12: Y | D12: Y
A13: 2910 | B13: https://github.com/EaminC/AgentBug-Smith/tree/main/results/all_combined_f2p/issue_2910_20260826T221655Z | C13: Y | D13: N
... A133: 1176 | B133: https://github.com/EaminC/AgentBug-Smith/tree/main/results/all_combined_f2p/issue_1176_20260815T110931Z | C133: Y | D133: Y
A135: DO NOT LABEL THIS LIST YET! I RE-WATCHED THE VIDEO AND I THINK THIS LIST IS NOT THE ONES WE SHOULD JUDGE.
A136: You can label the list below. Thanks!
A138: 1037 | B138: https://github.com/EaminC/AgentBug-Smith/blob/main/data/issues_80/issue_1037.json | D138: Y
A139: 109 | B139: https://github.com/EaminC/AgentBug-Smith/blob/main/data/issues_80/issue_109.json | D139: Y
A140: 1129 | B140: https://github.com/EaminC/AgentBug-Smith/blob/main/data/issues_80/issue_1129.json | D140: Y
A141: 1136 | B141: https://github.com/EaminC/AgentBug-Smith/blob/main/data/issues_80/issue_1136.json | C141: Y | D141: Y | E141: Y
A142: 1197 | B142: https://github.com/EaminC/AgentBug-Smith/blob/main/data/issues_80/issue_1197.json | C142: Y | D142: Y | E142: Y
A143: 121 | B143: https://github.com/EaminC/AgentBug-Smith/blob/main/data/issues_80/issue_121.json | C143: Y | D143: Y | E143: Y
A144: 1222 | B144: https://github.com/EaminC/AgentBug-Smith/blob/main/data/issues_80/issue_1222.json | C144: Y | D144: Y | E144: Y
A145: 1277 | B145: https://github.com/EaminC/AgentBug-Smith/blob/main/data/issues_80/issue_1277.json | C145: Y | D145: Y | E145: Y
A146: 1280 | B146: https://github.com/EaminC/AgentBug-Smith/blob/main/data/issues_80/issue_1280.json | C146: Y | D146: Y | E146: Y
A147: 137 | B147: https://github.com/EaminC/AgentBug-Smith/blob/main/data/issues_80/issue_137.json | D147: Y
A148: 1437 | B148: https://github.com/EaminC/AgentBug-Smith/blob/main/data/issues_80/issue_1437.json | D148: Y
A149: 1439 | B149: https://github.com/EaminC/AgentBug-Smith/blob/main/data/issues_80/issue_1439.json | C149: Y | D149: Y | E149: Y
A150: 1445 | B150: https://github.com/EaminC/AgentBug-Smith/blob/main/data/issues_80/issue_1445.json | D150: Y
A151: 1455 | B151: https://github.com/EaminC/AgentBug-Smith/blob/main/data/issues_80/issue_1455.json | D151: Y
A152: 149 | B152: https://github.com/EaminC/AgentBug-Smith/blob/main/data/issues_80/issue_149.json | D152: Y
A153: 1511 | B153: https://github.com/EaminC/AgentBug-Smith/blob/main/data/issues_80/issue_1511.json | D153: Y
A154: 1583 | B154: https://github.com/EaminC/AgentBug-Smith/blob/main/data/issues_80/issue_1583.json | D154: Y
A155: 1675 | B155: https://github.com/EaminC/AgentBug-Smith/blob/main/data/issues_80/issue_1675.json | C155: Y | D155: Y | E155: Y
A156: 169 | B156: https://github.com/EaminC/AgentBug-Smith/blob/main/data/issues_80/issue_169.json | C156: Y | D156: Y | E156: Y
A157: 174 | B157: https://github.com/EaminC/AgentBug-Smith/blob/main/data/issues_80/issue_174.json | D157: Y
A158: 177 | B158: https://github.com/EaminC/AgentBug-Smith/blob/main/data/issues_80/issue_177.json | D158: Y
A159: 1851 | B159: https://github.com/EaminC/AgentBug-Smith/blob/main/data/issues_80/issue_1851.json | D159: Y
A160: 1886 | B160: https://github.com/EaminC/AgentBug-Smith/blob/main/data/issues_80/issue_1886.json | D160: Y
A161: 1887 | B161: https://github.com/EaminC/AgentBug-Smith/blob/main/data/issues_80/issue_1887.json | D161: N
...

Sheet Summary
C2: GPT-4.1-mini | O2: Official price: | P2: $0.4 - input token/1M
P3: $1.6 - output token/1M
A4: No | B4: Pipeline | C4: F2P App (w/ in-Patch) | D4: F2P App (w/o in-patch) | E4: F2P App | F4: F2P Framework (w/ in-Patch) | G4: F2P Framework (w/o in-patch) | H4: F2P Framework | I4: Total F2P (w/ in-patch) | J4: Total F2P (w/o in-patch) | K4: Total F2P | L4: Avg. Duration | M4: Avg. Cost | N4: Avg. Token Consumption | O4: Env. build | P4: Avg. Input Token | Q4: Avg. Output Token
A5: 1 | B5: AgentBug-Smith | C5: =3+0+0+0 -> 3 | D5: =6+3+4+0 -> 13 | E5: =C5+D5 -> 16 | F5: =6+1+14+0 -> 21 | G5: =4+0+2+2 -> 8 | H5: =F5+G5 -> 29 | I5: =C5+F5 -> 24 | J5: =D5+G5 -> 21 | K5: =I5+J5 -> 45 | L5: 58m 10s | M5: =((P5/1000000)*0.4)+((Q5/1000000)*1.6) -> 0.5595124 | N5: =P5+Q5 -> 1287247 | O5: 84 | P5: 1250069 | Q5: 37178 | S5: *calc token by sampling 5 issues
A6: 2 | B6: SWE-Factory | C6: =3+0+0+0 -> 3 | D6: 0 | E6: =C6+D6 -> 3 | F6: =8+0+10+0 -> 18 | G6: 0 | H6: =F6+G6 -> 18 | I6: =C6+F6 -> 21 | J6: =D6+G6 -> 0 | K6: =I6+J6 -> 21 | L6: 5m 45s | M6: =((P6/1000000)*0.4)+((Q6/1000000)*1.6) -> 0.0906424 | N6: =P6+Q6 -> 167176 | O6: 36 | P6: 147366 | Q6: 19810 | S6: *calc token by sampling 5 issues
A7: 3 | B7: SWE-bench-Live | C7: =1+0+0+0 -> 1 | D7: 0 | E7: =C7+D7 -> 1 | F7: =3+1+1+0 -> 5 | G7: 0 | H7: =F7+G7 -> 5 | I7: =C7+F7 -> 6 | J7: =D7+G7 -> 0 | K7: =I7+J7 -> 6 | L7: 22m 19s | M7: =((P7/1000000)*0.4)+((Q7/1000000)*1.6) -> 0.4091236 | N7: =P7+Q7 -> 1007209 | O7: 33 | P7: 1002009 | Q7: 5200 | S7: *calc token by sampling 5 issues | V7: Use tuzi-gpt-mini
C11: Deepseek-v3.2 | O11: Official price | P11: $0.28 - input token/1M
P12: $0.4 - output token/1M
A13: No | B13: Pipeline | C13: F2P App (w/ in-Patch) | D13: F2P App (w/o in-patch) | E13: F2P App | F13: F2P Framework (w/ in-Patch) | G13: F2P Framework (w/o in-patch) | H13: F2P Framework | I13: Total F2P (w/ in-patch) | J13: Total F2P (w/o in-patch) | K13: Total F2P | L13: Avg. Duration | M13: Avg. Cost | N13: Avg. Token Consumption | O13: Env. build | P13: Avg. Input Token | Q13: Avg. Output Token
A14: 1 | B14: AgentBug-Smith | C14: 5 | D14: 21 | E14: =C14+D14 -> 26 | F14: 29 | G14: 8 | H14: =F14+G14 -> 37 | I14: =F14+C14 -> 34 | J14: =G14+D14 -> 29 | K14: =I14+J14 -> 63 | L14: 76m 26s | M14: =((P14/1000000)*0.28)+((Q14/1000000)*0.4) -> 2.4390618 | N14: =P14+Q14 -> 8667177 | O14: 93 | P14: 8565075 | Q14: 102102 | S14: *calc token by sampling 24 issues
A15: 2 | B15: SWE-Factory | C15: 3 | D15: 0 | E15: =C15+D15 -> 3 | F15: 28 | G15: 0 | H15: =F15+G15 -> 28 | I15: =F15+C15 -> 31 | J15: =G15+D15 -> 0 | K15: =I15+J15 -> 31 | L15: 6m 27s | M15: =((P15/1000000)*0.28)+((Q15/1000000)*0.4) -> 0.30701028 | N15: =P15+Q15 -> 1039926 | O15: 44 | P15: 908001 | Q15: 131925 | S15: *calc token using 2nd batch data
A16: 3 | B16: SWE-bench-Live | C16: 0 | D16: 0 | E16: =C16+D16 -> 0 | F16: 1 | G16: 0 | H16: =F16+G16 -> 1 | I16: =F16+C16 -> 1 | J16: =G16+D16 -> 0 | K16: =I16+J16 -> 1 | L16: 17m 22s | M16: =((P16/1000000)*0.28)+((Q16/1000000)*0.4) -> 1.0495557 | N16: =P16+Q16 -> 3738206 | O16: 14 | P16: 3714389 | Q16: 23817 | S16: *calc token by sampling 5 issues | V16: Use tuzi-baseline
C20: Kimi-k2.5 | O20: Official price | P20: $0.6 - input token/1M
P21: $3 - output token/1M
A22: No | B22: Pipeline | C22: F2P App (w/ in-Patch) | D22: F2P App (w/o in-patch) | E22: F2P App | F22: F2P Framework (w/ in-Patch) | G22: F2P Framework (w/o in-patch) | H22: F2P Framework | I22: Total F2P (w/ in-patch) | J22: Total F2P (w/o in-patch) | K22: Total F2P | L22: Avg. Duration | M22: Avg. Cost | N22: Avg. Token Consumption | O22: Env. build | P22: Avg. Input Token | Q22: Avg. Output Token
A23: 1 | B23: AgentBug-Smith | C23: 3 | D23: 22 | E23: =C23+D23 -> 25 | F23: 17 | G23: 4 | H23: =F23+G23 -> 21 | I23: =C23+F23 -> 20 | J23: =D23+G23 -> 26 | K23: =J23+I23 -> 46 | L23: 57m 15s | M23: =((P23/1000000)*0.6)+((Q23/1000000)*3) -> 0.9140562 | N23: =P23+Q23 -> 1285523 | O23: 53 | P23: 1226047 | Q23: 59476
A24: 2 | B24: SWE-Factory | C24: 2 | D24: 0 | E24: =C24+D24 -> 2 | F24: 17 | G24: 0 | H24: =F24+G24 -> 17 | I24: =C24+F24 -> 19 | J24: =D24+G24 -> 0 | K24: =J24+I24 -> 19 | L24: 4m 48s | M24: =((P24/1000000)*0.6)+((Q24/1000000)*3) -> 0.365214 | N24: =P24+Q24 -> 592602 | O24: 27 | P24: 588580 | Q24: 4022 | V24: Use tuzi-baseline
A25: 3 | B25: SWE-bench-Live | C25: 2 | D25: 0 | E25: =C25+D25 -> 2 | F25: 4 | G25: 0 | H25: =F25+G25 -> 4 | I25: =C25+F25 -> 6 | J25: =D25+G25 -> 0 | K25: =J25+I25 -> 6 | L25: 25m 14s | M25: =((P25/1000000)*0.6)+((Q25/1000000)*3) -> 0.6554874 | N25: =P25+Q25 -> 1065259 | O25: 29 | P25: 1058454 | Q25: 6805 | V25: Use tuzi-baseline
A28: AGENTBUG-SMITH
A29: No. | B29: Models | C29: App/Frame | D29: Agent Name | E29: Issue ID | F29: Issue PR | G29: In Patch? | H29: Agent Harness Component | I29: Reason | K29: Total F2P Across all models: | L29: 75 | N29: w/ IPT | O29: =COUNTIF(G30:G104,"Y") -> 35 | P29: 114 | Q29: =O29+P29 -> 149
A30: 1 | B30: GPT | Kimi | C30: Application | D30: gpt-engineer | E30: 9 | F30: 40 | H30: Lifecycle & Orchestration Loop | I30: Managing LLM backend routing, dynamic initialization fallbacks, and provider error recovery directly governs how the agent lifecycle initializes and executes its core generation turns. | N30: wo/ IPT | O30: =L29-O29 -> 40 | P30: 11 | Q30: =O30+P30 -> 51
A31: 2 | B31: Deepseek | Kimi | C31: Application | D31: mle-agent | E31: 29 | F31: 30 | H31: Lifecycle & Orchestration Loop | I31: This bug and its resolution pertain to how the agent structures its high-level execution stages, manages user-in-the-loop task planning, and orchestrates the setup steps prior to code synthesis and execution. | L31: w/ in-patch | M31: wo/ in-patch | N31: Total F2P | Q31: =Q29/200 -> 0.745
A32: 3 | B32: Deepseek | C32: Application | D32: mle-agent | E32: 33 | F32: 34 | H32: Lifecycle & Orchestration Loop | I32: Modifying the order of sequential stages, phase transitions, and user-in-the-loop interaction checkpoints directly alters the agent's high-level planning and lifecycle orchestration control flow. | K32: GPT only | L32: 0 | M32: 4 | N32: 4
A33: 4 | B33: Kimi | C33: Application | D33: mle-agent | E33: 56 | F33: 59 | H33: Tool Registry & Action Interface | I33: This issue directly concerns the setup, configuration, and interface initialization of an external tool provider (SearchAgent / search engine integration) before the agent can invoke it. | K33: Deepseek only | L33: 6 | M33: 7 | N33: 13
A34: 5 | B34: GPT | Deepseek | Kimi | C34: Application | D34: mle-agent | E34: 70 | F34: 73 | H34: Observability & Environment | I34: This enhancement directly serves user-facing inspection, operational visualization, and trajectory/state presentation of the agent's internal planning process without changing the underlying planning logic or execution control loop. | K34: Kimi only | L34: 0 | M34: 3 | N34: 3
A35: 6 | B35: GPT | Deepseek | Kimi | C35: Framework | D35: agentscope | E35: 71 | F35: 76 | H35: Context & Memory Management | I35: This issue directly concerns message/chat history data structures, prompt payload validation, and formatting representations as messages are converted from agent state/memory into model-consumable context lists. | K35: GPT | Deepseek | L35: 9 | M35: 3 | N35: 12
A36: 7 | B36: Deepseek | Kimi | C36: Framework | D36: dapr-agents | E36: 83 | F36: 84 | H36: Tool Registry & Action Interface | I36: This issue is fundamentally about tool result protocol parsing, serialization, and bidirectional communication between external tool interfaces (MCP) and the agent framework. | K36: GPT | Kimi | L36: 0 | M36: 5 | N36: 5
A37: 8 | B37: GPT | C37: Framework | D37: agentscope | E37: 91 | F37: 93 | H37: Lifecycle & Orchestration Loop | I37: This issue concerns multi-agent coordination, turn execution protocols, and message dispatch conventions within a multi-agent orchestration pattern (msghub). | K37: Deepseek | Kimi | L37: 5 | M37: 9 | N37: 14
A38: 9 | B38: GPT | Deepseek | C38: Framework | D38: agentscope | E38: 102 | F38: 106 | H38: Observability & Environment | I38: AgentScope Studio and its corresponding logging utilities form the monitoring, telemetry, and debugging interface used to trace and visualize agent conversations and runtime outputs. | K38: GPT | Deepseek | Kimi | L38: 14 | M38: 10 | N38: 24
A39: 10 | B39: Deepseek | Kimi | C39: Application | D39: mle-agent | E39: 121 | F39: 123 | H39: Context & Memory Management | I39: Session checkpointing, cross-session state persistence, and restoring serialized memory/context state across executions fall squarely under managing persistent agent memory and long-term state.
A40: 11 | B40: GPT | Deepseek |Kimi | C40: Application | D40: gpt-engineer | E40: 169 | F40: 173 | G40: Y | H40: Tool Registry & Action Interface | I40: This issue directly involves response parsing, action extraction, and output deserialization (parsing unstructured model generation into concrete environment actions and file operations).
A41: 12 | B41: Deepseek | Kimi | C41: Application | D41: mle-agent | E41: 182 | F41: 184 | H41: Observability & Environment | I41: The web dashboard and report viewer function as the user-facing inspection, operational monitoring, and visualization UI for the agent system's outputs and analytics.
A42: 13 | B42: GPT | Kimi | C42: Application | D42: mle-agent | E42: 159 | F42: 187 | H42: Lifecycle & Orchestration Loop | I42: This issue and fix directly modify the agent's interactive decision flow, clarifying question logic, and human-in-the-loop task planning loop during the initiation phase of the workflow. | K42: {=UNIQUE(D30:D104)} -> gpt-engineer | L42: =COUNTIF($D$30:$D$104,K42) -> 10
A43: 14 | B43: GPT | Deepseek | Kimi | C43: Framework | D43: agentscope | E43: 194 | F43: 197 | G43: Y | H43: Context & Memory Management | I43: This bug and patch directly address memory data models, memory loading/deserialization, and conversation history persistence within the agent's memory component. | K43: mle-agent | L43: =COUNTIF($D$30:$D$104,K43) -> 14
A44: 15 | B44: Deepseek | C44: Framework | D44: agentscope | E44: 196 | F44: 212 | H44: Lifecycle & Orchestration Loop | I44: This bug and fix directly govern game turn sequencing, environment state transitions, and episode termination conditions (stopping criteria) in an interactive multi-agent control loop. | K44: agentscope | L44: =COUNTIF($D$30:$D$104,K44) -> 16
A45: 16 | B45: GPT | C45: Application | D45: mle-agent | E45: 174 | F45: 217 | H45: Tool Registry & Action Interface | I45: Configuring, overriding, and adapting communication endpoints and initialization protocols for external APIs/LLM backends sits in the Action Interface layer (managing how the agent dials out to the model or tools). | K45: dapr-agents | L45: =COUNTIF($D$30:$D$104,K45) -> 2
A46: 17 | B46: GPT | Kimi | C46: Application | D46: mle-agent | E46: 166 | F46: 230 | H46: Tool Registry & Action Interface | I46: Integrating an LLM engine with function-calling capabilities requires implementing the tool schema translation, parameter serialization, and action dispatch layer between the agent framework and the provider API. | K46: open-interpreter | L46: =COUNTIF($D$30:$D$104,K46) -> 2
A47: 18 | B47: Deepseek | C47: Application | D47: mle-agent | E47: 259 | F47: 262 | H47: Observability & Environment | I47: This bug and fix directly impact the configuration, routing, and operational file storage of the agent framework's logging and telemetry subsystems. | K47: aider | L47: =COUNTIF($D$30:$D$104,K47) -> 7
A48: 19 | B48: GPT | Deepseek | Kimi | C48: Application | D48: mle-agent | E48: 266 | F48: 269 | H48: Context & Memory Management | I48: This issue directly modifies the underlying vector store and long-term memory retrieval/persistence layer used to store and manage external knowledge, facts, and embeddings for the agent. | K48: strands-agents | L48: =COUNTIF($D$30:$D$104,K48) -> 1
A49: 20 | B49: GPT | Kimi | C49: Application | D49: mle-agent | E49: 270 | F49: 271 | H49: Context & Memory Management | I49: The core functionality directly manages the ingestion, vector storage, indexing, and CRUD lifecycle of external knowledge and long-term memory for the agent. | K49: crewai | L49: =COUNTIF($D$30:$D$104,K49) -> 16
...

Sheet SE Agent Experiment
A1: Resolved by 3 agents | B1: Correctly resolved by mini-swe-agent & auto-code-rover | C1: Correctly resolved by mini-swe-agent and openhands | D1: Correct resolved by auto-code-rover & openhands
A3: Mini-swe-agent | C3: * the generated patch has similar fix but it has either less or more changes than ground truth
A4: Issue ID | B4: Harness Component | C4: Correctly Resolved | E4: Summary of Plausible Resolved
A5: 141 | B5: {=_xlfn.XLOOKUP(A5, Summary!$E$30:$E$234,Summary!$H$30:$H$234, "Not Found")} -> Tool Registry & Action Interface | C5: N | E5: {=UNIQUE(B5:B43)} -> Tool Registry & Action Interface | F5: =COUNTIF($B$5:$B$43,E5) -> 12
A6: 159 | B6: {=_xlfn.XLOOKUP(A6, Summary!$E$30:$E$234,Summary!$H$30:$H$234, "Not Found")} -> Lifecycle & Orchestration Loop | C6: N | D6: * | E6: Lifecycle & Orchestration Loop | F6: =COUNTIF($B$5:$B$43,E6) -> 11
A7: 160 | B7: {=_xlfn.XLOOKUP(A7, Summary!$E$30:$E$234,Summary!$H$30:$H$234, "Not Found")} -> Tool Registry & Action Interface | C7: N | E7: Context & Memory Management | F7: =COUNTIF($B$5:$B$43,E7) -> 9
A8: 298 | B8: {=_xlfn.XLOOKUP(A8, Summary!$E$30:$E$234,Summary!$H$30:$H$234, "Not Found")} -> Context & Memory Management | C8: N | E8: Observability & Environment | F8: =COUNTIF($B$5:$B$43,E8) -> 7
A9: 509 | B9: {=_xlfn.XLOOKUP(A9, Summary!$E$30:$E$234,Summary!$H$30:$H$234, "Not Found")} -> Context & Memory Management | C9: N
A10: 962 | B10: {=_xlfn.XLOOKUP(A10, Summary!$E$30:$E$234,Summary!$H$30:$H$234, "Not Found")} -> Context & Memory Management | C10: N | E10: Total Correctly Resolved | F10: =COUNTIF(C5:C43, "Y") -> 18
A11: 974 | B11: {=_xlfn.XLOOKUP(A11, Summary!$E$30:$E$234,Summary!$H$30:$H$234, "Not Found")} -> Context & Memory Management | C11: Y
A12: 1210 | B12: {=_xlfn.XLOOKUP(A12, Summary!$E$30:$E$234,Summary!$H$30:$H$234, "Not Found")} -> Tool Registry & Action Interface | C12: Y | E12: Summary of Correctly Resolved
A13: 1277 | B13: {=_xlfn.XLOOKUP(A13, Summary!$E$30:$E$234,Summary!$H$30:$H$234, "Not Found")} -> Tool Registry & Action Interface | C13: Y | E13: {=UNIQUE(B5:B43)} -> Tool Registry & Action Interface | F13: =COUNTIFS($B$5:$B$43,E13,$C$5:$C$43,"Y") -> 6
A14: 1280 | B14: {=_xlfn.XLOOKUP(A14, Summary!$E$30:$E$234,Summary!$H$30:$H$234, "Not Found")} -> Lifecycle & Orchestration Loop | C14: Y | E14: Lifecycle & Orchestration Loop | F14: =COUNTIFS($B$5:$B$43,E14,$C$5:$C$43,"Y") -> 5
A15: 1297 | B15: {=_xlfn.XLOOKUP(A15, Summary!$E$30:$E$234,Summary!$H$30:$H$234, "Not Found")} -> Observability & Environment | C15: Y | E15: Context & Memory Management | F15: =COUNTIFS($B$5:$B$43,E15,$C$5:$C$43,"Y") -> 3
A16: 1583 | B16: {=_xlfn.XLOOKUP(A16, Summary!$E$30:$E$234,Summary!$H$30:$H$234, "Not Found")} -> Tool Registry & Action Interface | C16: N | E16: Observability & Environment | F16: =COUNTIFS($B$5:$B$43,E16,$C$5:$C$43,"Y") -> 4
A17: 1596 | B17: {=_xlfn.XLOOKUP(A17, Summary!$E$30:$E$234,Summary!$H$30:$H$234, "Not Found")} -> Lifecycle & Orchestration Loop | C17: N
A18: 1688 | B18: {=_xlfn.XLOOKUP(A18, Summary!$E$30:$E$234,Summary!$H$30:$H$234, "Not Found")} -> Lifecycle & Orchestration Loop | C18: N
A19: 1702 | B19: {=_xlfn.XLOOKUP(A19, Summary!$E$30:$E$234,Summary!$H$30:$H$234, "Not Found")} -> Lifecycle & Orchestration Loop | C19: N
A20: 1792 | B20: {=_xlfn.XLOOKUP(A20, Summary!$E$30:$E$234,Summary!$H$30:$H$234, "Not Found")} -> Observability & Environment | C20: N
A21: 1813 | B21: {=_xlfn.XLOOKUP(A21, Summary!$E$30:$E$234,Summary!$H$30:$H$234, "Not Found")} -> Tool Registry & Action Interface | C21: Y
A22: 1885 | B22: {=_xlfn.XLOOKUP(A22, Summary!$E$30:$E$234,Summary!$H$30:$H$234, "Not Found")} -> Observability & Environment | C22: N
A23: 1900 | B23: {=_xlfn.XLOOKUP(A23, Summary!$E$30:$E$234,Summary!$H$30:$H$234, "Not Found")} -> Tool Registry & Action Interface | C23: N | D23: *
A24: 1904 | B24: {=_xlfn.XLOOKUP(A24, Summary!$E$30:$E$234,Summary!$H$30:$H$234, "Not Found")} -> Lifecycle & Orchestration Loop | C24: Y
A25: 2007 | B25: {=_xlfn.XLOOKUP(A25, Summary!$E$30:$E$234,Summary!$H$30:$H$234, "Not Found")} -> Observability & Environment | C25: Y
A26: 2055 | B26: {=_xlfn.XLOOKUP(A26, Summary!$E$30:$E$234,Summary!$H$30:$H$234, "Not Found")} -> Observability & Environment | C26: N
A27: 2089 | B27: {=_xlfn.XLOOKUP(A27, Summary!$E$30:$E$234,Summary!$H$30:$H$234, "Not Found")} -> Lifecycle & Orchestration Loop | C27: Y
A28: 2166 | B28: {=_xlfn.XLOOKUP(A28, Summary!$E$30:$E$234,Summary!$H$30:$H$234, "Not Found")} -> Observability & Environment | C28: Y
A29: 2173 | B29: {=_xlfn.XLOOKUP(A29, Summary!$E$30:$E$234,Summary!$H$30:$H$234, "Not Found")} -> Context & Memory Management | C29: N
A30: 2177 | B30: {=_xlfn.XLOOKUP(A30, Summary!$E$30:$E$234,Summary!$H$30:$H$234, "Not Found")} -> Tool Registry & Action Interface | C30: Y
A31: 2179 | B31: {=_xlfn.XLOOKUP(A31, Summary!$E$30:$E$234,Summary!$H$30:$H$234, "Not Found")} -> Tool Registry & Action Interface | C31: N
A32: 2235 | B32: {=_xlfn.XLOOKUP(A32, Summary!$E$30:$E$234,Summary!$H$30:$H$234, "Not Found")} -> Observability & Environment | C32: Y
A33: 2266 | B33: {=_xlfn.XLOOKUP(A33, Summary!$E$30:$E$234,Summary!$H$30:$H$234, "Not Found")} -> Lifecycle & Orchestration Loop | C33: N
A34: 2330 | B34: {=_xlfn.XLOOKUP(A34, Summary!$E$30:$E$234,Summary!$H$30:$H$234, "Not Found")} -> Tool Registry & Action Interface | C34: N
A35: 2587 | B35: {=_xlfn.XLOOKUP(A35, Summary!$E$30:$E$234,Summary!$H$30:$H$234, "Not Found")} -> Context & Memory Management | C35: N
... A43: 6050 | B43: {=_xlfn.XLOOKUP(A43, Summary!$E$30:$E$234,Summary!$H$30:$H$234, "Not Found")} -> Lifecycle & Orchestration Loop | C43: Y
A46: auto-code-rover
A47: Issue ID | B47: Harness Component | C47: Correctly Resolved | E47: Summary of Plausible Resolved
A48: 56 | B48: {=_xlfn.XLOOKUP(A48, Summary!$E$30:$E$234,Summary!$H$30:$H$234, "Not Found")} -> Tool Registry & Action Interface | C48: N | E48: {=UNIQUE(B48:B59)} -> Tool Registry & Action Interface | F48: =COUNTIF($B$48:$B$59,E48) -> 4
A49: 83 | B49: {=_xlfn.XLOOKUP(A49, Summary!$E$30:$E$234,Summary!$H$30:$H$234, "Not Found")} -> Tool Registry & Action Interface | C49: N | E49: Context & Memory Management | F49: =COUNTIF($B$48:$B$59,E49) -> 2
A50: 1112 | B50: {=_xlfn.XLOOKUP(A50, Summary!$E$30:$E$234,Summary!$H$30:$H$234, "Not Found")} -> Context & Memory Management | C50: N | E50: Lifecycle & Orchestration Loop | F50: =COUNTIF($B$48:$B$59,E50) -> 3
...

Sheet Agent Harness Components
A2: No. | B2: Components | C2: Description
A3: 1 | B3: Tool Registry & Action Interface | C3: The registry, interface, and protocol (e.g., MCP, function schemas) for discovering tools, formatting calls, and parsing observations/tool results.
A4: 2 | B4: Context & Memory Management | C4: Context window assembly, token budgeting, persistent storage (vector/relational/KV memory), retrieval (RAG), and state tracking.
A5: 3 | B5: Lifecycle & Orchestration Loop | C5: The agent control flow: the observe-think-act inner loop, multi-agent coordination, sub-task planning/routing, retry strategies, and termination conditions.
A6: 4 | B6: Observability & Environment | C6: Trajectory tracing, token/cost tracking, error logging, event telemetry, and debugging/replay infrastructure.
A7: 5 | B7: Governance, Security & Verification | C7: Runtime policy enforcement (permissions, guardrails, human-in-the-loop gates) and trajectory evaluation/verification (grounding, deterministic checks, safety assertions).

Sheet Agent Distribution - GPT
A1: AGENT FRAMEWORKS
I2: GPT-4.1-Mini
A3: No | B3: Repository | C3: Repo link | D3: Language | E3: Stars | F3: License | G3: Total Issues with In-Patch (on 80) | H3: Total Issues without In-Patch (on 80) | I3: Total Issues (on 80) | J3: Total F2P With In-Patch (on 80) | K3: Total F2P Without In-Patch (on 80) | L3: Total F2P (on 80) | M3: 第 13 列 | N3: Total Issues with In-Patch (on 70) | O3: Total Issues without In-Patch (on 70) | P3: Total Issues (on 70) | Q3: Total F2P With In-Patch (on 70) | R3: Total F2P Without In-Patch (on 70) | S3: Total F2P (on 70) | T3: Column 17 | U3: Total Issues with In-Patch (on 50) | V3: Total Issues without In-Patch (on 50) | W3: Total Issues (on 50) | X3: Total F2P With In-Patch (on 50) | Y3: Total F2P Without In-Patch (on 50) | Z3: Total F2P (data: 50) | AA3: Column 17 2 | AB3: Total Issues with In-Patch (on 25) | AC3: Total Issues without In-Patch (on 25) | AD3: Total Issues (on 25) | AE3: Total F2P With In-Patch (on 25) | AF3: Total F2P Without In-Patch (on 25) | AG3: Total F2P (data: 25) | AH3: Column 17 3 | AI3: Total Issues with In-Patch | AJ3: Total Issues without In-Patch | AK3: Total Issues | AL3: Total F2P
A4: 1 | B4: dapr/dapr-agents | C4: https://github.com/dapr/dapr-agents/ | D4: Python | E4: 650 | F4: Apache-2.0 license | G4: 1 | H4: 2 | I4: =G4+H4 -> 3 | J4: 0 | K4: 1 | L4: =J4+K4 -> 1 | N4: 0 | O4: 0 | P4: =N4+O4 -> 0 | S4: =Q4+R4 -> 0 | U4: 0 | V4: 0 | W4: =U4+V4 -> 0 | Z4: =X4+Y4 -> 0 | AD4: =AB4+AC4 -> 0 | AG4: =AE4+AF4 -> 0 | AI4: =G4+N4+U4+AB4 -> 1 | AJ4: =H4+O4+V4+AC4 -> 2 | AK4: =I4+P4+W4+AD4 -> 3 | AL4: =L4+S4+Z4+AG4 -> 1
A5: 2 | B5: VoltAgent/voltagent | C5: https://github.com/VoltAgent/voltagent/ | D5: Typescript | E5: 7.1k | F5: MIT license | G5: 0 | H5: 1 | I5: =G5+H5 -> 1 | L5: =J5+K5 -> 0 | N5: 0 | O5: 0 | P5: =N5+O5 -> 0 | S5: =Q5+R5 -> 0 | U5: 0 | V5: 0 | W5: =U5+V5 -> 0 | Z5: =X5+Y5 -> 0 | AD5: =AB5+AC5 -> 0 | AG5: =AE5+AF5 -> 0 | AI5: =G5+N5+U5+AB5 -> 0 | AJ5: =H5+O5+V5+AC5 -> 1 | AK5: =I5+P5+W5+AD5 -> 1 | AL5: =L5+S5+Z5+AG5 -> 0
A6: 3 | B6: agentscope-ai/agentscope | C6: https://github.com/agentscope-ai/agentscope/ | D6: Python | E6: 22.5k | F6: Apache-2.0 license | G6: 4 | H6: 8 | I6: =G6+H6 -> 12 | J6: 4 | K6: 3 | L6: =J6+K6 -> 7 | N6: 2 | O6: 0 | P6: =N6+O6 -> 2 | Q6: 1 | R6: 0 | S6: =Q6+R6 -> 1 | U6: 4 | V6: 6 | W6: =U6+V6 -> 10 | X6: 4 | Y6: 2 | Z6: =X6+Y6 -> 6 | AB6: 0 | AC6: 5 | AD6: =AB6+AC6 -> 5 | AE6: 0 | AF6: 1 | AG6: =AE6+AF6 -> 1 | AI6: =G6+N6+U6+AB6 -> 10 | AJ6: =H6+O6+V6+AC6 -> 19 | AK6: =I6+P6+W6+AD6 -> 29 | AL6: =L6+S6+Z6+AG6 -> 15
A7: 4 | B7: crewAIInc/crewAI | C7: https://github.com/crewAIInc/crewAI | D7: Python | E7: 47.6k | F7: MIT license | G7: 2 | H7: 5 | I7: =G7+H7 -> 7 | J7: 1 | K7: 0 | L7: =J7+K7 -> 1 | N7: 0 | O7: 0 | P7: =N7+O7 -> 0 | S7: =Q7+R7 -> 0 | U7: 26 | V7: 0 | W7: =U7+V7 -> 26 | X7: 10 | Y7: 0 | Z7: =X7+Y7 -> 10 | AB7: 0 | AC7: 16 | AD7: =AB7+AC7 -> 16 | AE7: 0 | AF7: 1 | AG7: =AE7+AF7 -> 1 | AI7: =G7+N7+U7+AB7 -> 28 | AJ7: =H7+O7+V7+AC7 -> 21 | AK7: =I7+P7+W7+AD7 -> 49 | AL7: =L7+S7+Z7+AG7 -> 12
A8: 5 | B8: strands-agents/harness-sdk | C8: https://github.com/strands-agents/sdk-python | D8: Python | E8: 5.5k | F8: Apache-2.0 license | G8: 1 | H8: 0 | I8: =G8+H8 -> 1 | J8: 1 | K8: 0 | L8: =J8+K8 -> 1 | N8: 0 | O8: 0 | P8: =N8+O8 -> 0 | S8: =Q8+R8 -> 0 | U8: 0 | V8: 0 | W8: =U8+V8 -> 0 | Z8: =X8+Y8 -> 0 | AD8: =AB8+AC8 -> 0 | AG8: =AE8+AF8 -> 0 | AI8: =G8+N8+U8+AB8 -> 1 | AJ8: =H8+O8+V8+AC8 -> 0 | AK8: =I8+P8+W8+AD8 -> 1 | AL8: =L8+S8+Z8+AG8 -> 1
A9: 6 | B9: mastra-ai/mastra | C9: https://github.com/mastra-ai/mastra | D9: Typescript | E9: 22.5k | F9: Apache-2.0 license | G9: 0 | H9: 2 | I9: =G9+H9 -> 2 | L9: =J9+K9 -> 0 | N9: 0 | O9: 0 | P9: =N9+O9 -> 0 | S9: =Q9+R9 -> 0 | U9: 0 | V9: 0 | W9: =U9+V9 -> 0 | Z9: =X9+Y9 -> 0 | AB9: 0 | AC9: 1 | AD9: =AB9+AC9 -> 1 | AG9: =AE9+AF9 -> 0 | AI9: =G9+N9+U9+AB9 -> 0 | AJ9: =H9+O9+V9+AC9 -> 3 | AK9: =I9+P9+W9+AD9 -> 3 | AL9: =L9+S9+Z9+AG9 -> 0
A10: 7 | B10: langchain-ai/langgraph | C10: https://github.com/langchain-ai/langgraph | D10: Python | E10: 28.4k | F10: MIT license | G10: 11 | H10: 2 | I10: =G10+H10 -> 13 | L10: =J10+K10 -> 0 | N10: 0 | O10: 0 | P10: =N10+O10 -> 0 | S10: =Q10+R10 -> 0 | U10: 0 | V10: 0 | W10: =U10+V10 -> 0 | Z10: =X10+Y10 -> 0 | AD10: =AB10+AC10 -> 0 | AG10: =AE10+AF10 -> 0 | AI10: =G10+N10+U10+AB10 -> 11 | AJ10: =H10+O10+V10+AC10 -> 2 | AK10: =I10+P10+W10+AD10 -> 13 | AL10: =L10+S10+Z10+AG10 -> 0
A11: 8 | B11: langflow-ai/langflow | C11: https://github.com/langflow-ai/langflow | D11: Python | E11: 148k | F11: MIT license | G11: 0 | H11: 0 | I11: =G11+H11 -> 0 | L11: =J11+K11 -> 0 | N11: 9 | O11: 2 | P11: =N11+O11 -> 11 | S11: =Q11+R11 -> 0 | U11: 0 | V11: 0 | W11: =U11+V11 -> 0 | Z11: =X11+Y11 -> 0 | AD11: =AB11+AC11 -> 0 | AG11: =AE11+AF11 -> 0 | AI11: =G11+N11+U11+AB11 -> 9 | AJ11: =H11+O11+V11+AC11 -> 2 | AK11: =I11+P11+W11+AD11 -> 11 | AL11: =L11+S11+Z11+AG11 -> 0
A12: 9 | B12: geekan/MetaGPT | C12: https://github.com/geekan/MetaGPT | D12: Python | E12: 67.9k | F12: MIT license | G12: 1 | H12: 0 | I12: =G12+H12 -> 1 | L12: =J12+K12 -> 0 | N12: 6 | O12: 5 | P12: =N12+O12 -> 11 | S12: =Q12+R12 -> 0 | U12: 0 | V12: 0 | W12: =U12+V12 -> 0 | Z12: =X12+Y12 -> 0 | AD12: =AB12+AC12 -> 0 | AG12: =AE12+AF12 -> 0 | AI12: =G12+N12+U12+AB12 -> 7 | AJ12: =H12+O12+V12+AC12 -> 5 | AK12: =I12+P12+W12+AD12 -> 12 | AL12: =L12+S12+Z12+AG12 -> 0
A13: 10 | B13: tensorzero/tensorzero | C13: https://github.com/tensorzero/tensorzero | D13: Rust | E13: 11.4k | F13: Apache-2.0 license | G13: 0 | H13: 0 | I13: =G13+H13 -> 0 | L13: =J13+K13 -> 0 | N13: 11 | O13: 0 | P13: =N13+O13 -> 11 | S13: =Q13+R13 -> 0 | U13: 0 | V13: 0 | W13: =U13+V13 -> 0 | Z13: =X13+Y13 -> 0 | AD13: =AB13+AC13 -> 0 | AG13: =AE13+AF13 -> 0 | AI13: =G13+N13+U13+AB13 -> 11 | AJ13: =H13+O13+V13+AC13 -> 0 | AK13: =I13+P13+W13+AD13 -> 11 | AL13: =L13+S13+Z13+AG13 -> 0
B14: TOTAL | G14: =SUM(G4:G13) -> 20 | H14: =SUM(H4:H13) -> 20 | I14: =SUM(I4:I13) -> 40 | J14: =SUM(J4:J13) -> 6 | K14: =SUM(K4:K13) -> 4 | L14: =SUM(L4:L13) -> 10 | N14: =SUM(N4:N13) -> 28 | O14: =SUM(O4:O13) -> 7 | P14: =SUM(P4:P13) -> 35 | Q14: =SUM(Q4:Q13) -> 1 | R14: =SUM(R4:R13) -> 0 | S14: =SUM(S4:S13) -> 1 | U14: =SUM(U4:U13) -> 30 | V14: =SUM(V4:V13) -> 6 | W14: =SUM(W4:W13) -> 36 | X14: =SUM(X4:X13) -> 14 | Y14: =SUM(Y4:Y13) -> 2 | Z14: =SUM(Z4:Z13) -> 16 | AB14: =SUM(AB4:AB13) -> 0 | AC14: =SUM(AC4:AC13) -> 22 | AD14: =SUM(AD4:AD13) -> 22 | AE14: =SUM(AE4:AE13) -> 0 | AF14: =SUM(AF4:AF13) -> 2 | AG14: =SUM(AG4:AG13) -> 2 | AI14: =G14+N14+U14+AB14 -> 78 | AJ14: =H14+O14+V14+AC14 -> 55 | AK14: =SUM(AK4:AK13) -> 133 | AL14: =SUM(AL4:AL13) -> 29
A17: AGENT APPLICATIONS
I18: GPT-4.1-Mini
A19: No | B19: Repository | C19: Repo link | D19: Language | E19: Stars | F19: License | G19: Total Issues with In-Patch (on 80) | H19: Total Issues without In-Patch (on 80) | I19: Total Issues (on 80) | J19: Total F2P In-Patch (on 80) | K19: Total F2P No In-Patch (on 80) | L19: Total F2P (on 80) | M19: 第 13 列 | N19: Total Issues with In-Patch (on 70) | O19: Total Issues without In-Patch (on 70) | P19: Total Issues (on 70) | Q19: Total F2P With In-Patch (on 70) | R19: Total F2P Without In-Patch (on 70) | S19: Total F2P (on 70) | T19: Column 17 | U19: Total Issues with In-Patch (on 50) | V19: Total Issues without In-Patch (on 50) | W19: Total Issues (on 50) | X19: Total F2P With In-Patch (on 50) | Y19: Total F2P Without In-Patch (on 50) | Z19: Total F2P (data: 50) | AA19: Column 17 2 | AB19: Total Issues with In-Patch (on 25) | AC19: Total Issues without In-Patch (on 25) | AD19: Total Issues (on 25) | AE19: Total F2P With In-Patch (on 25) | AF19: Total F2P Without In-Patch (on 25) | AG19: Total F2P (data: 25) | AH19: Column 17 3 | AI19: Total Issues with In-Patch | AJ19: Total Issues without In-Patch | AK19: Total Issues | AL19: Total F2P
A20: 1 | B20: Significant-Gravitas/AutoGPT | C20: https://github.com/Significant-Gravitas/AutoGPT | D20: Python | E20: 183k | F20: MIT License & PolyForm Shield License 1.0.0 | G20: 4 | H20: 1 | I20: =G20+H20 -> 5 | L20: =J20+K20 -> 0 | N20: 0 | O20: 0 | P20: =N20+O20 -> 0 | U20: 6 | V20: 2 | W20: =U20+V20 -> 8 | Z20: =X20+Y20 -> 0 | AD20: =AB20+AC20 -> 0 | AG20: =AE20+AF20 -> 0 | AI20: =G20+N20+U20+AB20 -> 10 | AJ20: =H20+O20+V20+AC20 -> 3 | AK20: =I20+P20+W20+AD20 -> 13 | AL20: =L20+S20+Z20+AG20 -> 0
A21: 2 | B21: MLSysOps/MLE-agent | C21: https://github.com/MLSysOps/MLE-agent/ | D21: Python | E21: 1.5k | F21: MIT license | G21: 0 | H21: 9 | I21: =G21+H21 -> 9 | J21: 0 | K21: 2 | L21: =J21+K21 -> 2 | N21: 0 | O21: 8 | P21: =N21+O21 -> 8 | Q21: 0 | R21: 3 | S21: 3 | U21: 0 | V21: 1 | W21: =U21+V21 -> 1 | X21: 0 | Y21: 1 | Z21: =X21+Y21 -> 1 | AB21: 0 | AC21: 3 | AD21: =AB21+AC21 -> 3 | AE21: 0 | AF21: 0 | AG21: =AE21+AF21 -> 0 | AI21: =G21+N21+U21+AB21 -> 0 | AJ21: =H21+O21+V21+AC21 -> 21 | AK21: =I21+P21+W21+AD21 -> 21 | AL21: =L21+S21+Z21+AG21 -> 6
A22: 3 | B22: always-further/AgentUp | C22: https://github.com/always-further/AgentUp/ | D22: Python | E22: 100 | F22: Apache-2.0 license | G22: 0 | H22: 2 | I22: =G22+H22 -> 2 | L22: =J22+K22 -> 0 | N22: 0 | O22: 0 | P22: =N22+O22 -> 0 | U22: 0 | V22: 0 | W22: =U22+V22 -> 0 | Z22: =X22+Y22 -> 0 | AD22: =AB22+AC22 -> 0 | AG22: =AE22+AF22 -> 0 | AI22: =G22+N22+U22+AB22 -> 0 | AJ22: =H22+O22+V22+AC22 -> 2 | AK22: =I22+P22+W22+AD22 -> 2 | AL22: =L22+S22+Z22+AG22 -> 0
A23: 4 | B23: Canner/WrenAI | C23: https://github.com/Canner/WrenAI | D23: Python | E23: 14.9k | F23: AGPL-3.0 license | G23: 0 | H23: 1 | I23: =G23+H23 -> 1 | L23: =J23+K23 -> 0 | N23: 0 | O23: 0 | P23: =N23+O23 -> 0 | U23: 0 | V23: 0 | W23: =U23+V23 -> 0 | Z23: =X23+Y23 -> 0 | AD23: =AB23+AC23 -> 0 | AG23: =AE23+AF23 -> 0 | AI23: =G23+N23+U23+AB23 -> 0 | AJ23: =H23+O23+V23+AC23 -> 1 | AK23: =I23+P23+W23+AD23 -> 1 | AL23: =L23+S23+Z23+AG23 -> 0
A24: 5 | B24: reworkd/AgentGPT | C24: https://github.com/reworkd/AgentGPT | D24: Python | E24: 35.9k | F24: GPL-3.0 license | G24: 1 | H24: 4 | I24: =G24+H24 -> 5 | L24: =J24+K24 -> 0 | N24: 0 | O24: 0 | P24: =N24+O24 -> 0 | U24: 0 | V24: 0 | W24: =U24+V24 -> 0 | Z24: =X24+Y24 -> 0 | AD24: =AB24+AC24 -> 0 | AG24: =AE24+AF24 -> 0 | AI24: =G24+N24+U24+AB24 -> 1 | AJ24: =H24+O24+V24+AC24 -> 4 | AK24: =I24+P24+W24+AD24 -> 5 | AL24: =L24+S24+Z24+AG24 -> 0
A25: 6 | B25: Aider-AI/aider | C25: https://github.com/Aider-AI/aider | D25: Python | E25: 42.8k | F25: Apache-2.0 license | G25: 1 | H25: 6 | I25: =G25+H25 -> 7 | J25: 1 | K25: 4 | L25: =J25+K25 -> 5 | N25: 0 | O25: 0 | P25: =N25+O25 -> 0 | U25: 0 | V25: 0 | W25: =U25+V25 -> 0 | Z25: =X25+Y25 -> 0 | AD25: =AB25+AC25 -> 0 | AG25: =AE25+AF25 -> 0 | AI25: =G25+N25+U25+AB25 -> 1 | AJ25: =H25+O25+V25+AC25 -> 6 | AK25: =I25+P25+W25+AD25 -> 7 | AL25: =L25+S25+Z25+AG25 -> 5
A26: 7 | B26: ValueCell-ai/valuecell | C26: https://github.com/ValueCell-ai/valuecell | D26: Python | E26: 10.2k | F26: Apache-2.0 license | G26: 0 | H26: 4 | I26: =G26+H26 -> 4 | L26: =J26+K26 -> 0 | N26: 0 | O26: 1 | P26: =N26+O26 -> 1 | U26: 0 | V26: 0 | W26: =U26+V26 -> 0 | Z26: =X26+Y26 -> 0 | AD26: =AB26+AC26 -> 0 | AG26: =AE26+AF26 -> 0 | AI26: =G26+N26+U26+AB26 -> 0 | AJ26: =H26+O26+V26+AC26 -> 5 | AK26: =I26+P26+W26+AD26 -> 5 | AL26: =L26+S26+Z26+AG26 -> 0
A27: 8 | B27: AntonOsika/gpt-engineer | C27: https://github.com/AntonOsika/gpt-engineer | D27: Python | E27: 55.2k | F27: MIT license | G27: 4 | H27: 3 | I27: =G27+H27 -> 7 | J27: 2 | K27: 0 | L27: =J27+K27 -> 2 | N27: 4 | O27: 3 | P27: =N27+O27 -> 7 | U27: 1 | V27: 4 | W27: =U27+V27 -> 5 | X27: 0 | Y27: 3 | Z27: =X27+Y27 -> 3 | AD27: =AB27+AC27 -> 0 | AG27: =AE27+AF27 -> 0 | AI27: =G27+N27+U27+AB27 -> 9 | AJ27: =H27+O27+V27+AC27 -> 10 | AK27: =I27+P27+W27+AD27 -> 19 | AL27: =L27+S27+Z27+AG27 -> 5
A28: 9 | B28: OpenInterpreter/open-interpreter | C28: https://github.com/OpenInterpreter/open-interpreter | D28: Python | E28: 11.4k | F28: Apache-2.0 license | G28: 0 | H28: 0 | I28: =G28+H28 -> 0 | L28: =J28+K28 -> 0 | N28: 0 | O28: 12 | P28: =N28+O28 -> 12 | U28: 0 | V28: 0 | W28: =U28+V28 -> 0 | Z28: =X28+Y28 -> 0 | AD28: =AB28+AC28 -> 0 | AG28: =AE28+AF28 -> 0 | AI28: =G28+N28+U28+AB28 -> 0 | AJ28: =H28+O28+V28+AC28 -> 12 | AK28: =I28+P28+W28+AD28 -> 12 | AL28: =L28+S28+Z28+AG28 -> 0
A29: 10 | B29: lobehub/lobehub | C29: https://github.com/lobehub/lobehub | D29: Typescript | E29: 77k | F29: Apache-2.0 license | G29: 0 | H29: 0 | I29: =G29+H29 -> 0 | L29: =J29+K29 -> 0 | N29: 7 | O29: 0 | P29: =N29+O29 -> 7 | U29: 0 | V29: 0 | W29: =U29+V29 -> 0 | Z29: =X29+Y29 -> 0 | AD29: =AB29+AC29 -> 0 | AG29: =AE29+AF29 -> 0 | AI29: =G29+N29+U29+AB29 -> 7 | AJ29: =H29+O29+V29+AC29 -> 0 | AK29: =I29+P29+W29+AD29 -> 7 | AL29: =L29+S29+Z29+AG29 -> 0
B30: TOTAL | G30: =G29+G28+G27+G26+G25+G24+G23+G22+G21+G20 -> 10 | H30: =H29+H28+H27+H26+H25+H24+H23+H22+H21+H20 -> 30 | I30: =SUM(I20:I29) -> 40 | J30: =SUM(J20:J29) -> 3 | K30: =SUM(K20:K29) -> 6 | L30: =SUM(L20:L29) -> 9 | N30: =SUM(AGENT_APPLICATIONS[Total Issues with In-Patch (on 70)]) -> 11 | O30: =SUM(AGENT_APPLICATIONS[Total Issues without In-Patch (on 70)]) -> 24 | P30: =SUM(P20:P29) -> 35 | Q30: =SUM(Q20:Q29) -> 0 | R30: =SUM(R20:R29) -> 3 | S30: =SUM(S20:S29) -> 3 | U30: =SUM(U20:U29) -> 7 | V30: =SUM(V20:V29) -> 7 | W30: =SUM(W20:W29) -> 14 | X30: =SUM(X20:X29) -> 0 | Y30: =SUM(Y20:Y29) -> 4 | Z30: =SUM(Z20:Z29) -> 4 | AB30: =SUM(AGENT_APPLICATIONS[Total Issues with In-Patch (on 25)]) -> 0 | AC30: =SUM(AGENT_APPLICATIONS[Total Issues without In-Patch (on 25)]) -> 3 | AD30: =SUM(AGENT_APPLICATIONS[Total Issues (on 25)]) -> 3 | AE30: 0 | AF30: 0 | AG30: 0 | AK30: =SUM(AGENT_APPLICATIONS[Total Issues]) -> 92 | AL30: =SUM(AGENT_APPLICATIONS[Total F2P]) -> 16
A33: SUMMARY
A35: No | B35: Batch | C35: Issues with In-Patch | D35: Issues without In-Patch | E35: F2P with In-Patch | F35: F2P without In-Patch | G35: Total F2P | H35: SWE-Factory F2P | I35: SWE-bench-Live F2P
A36: 1 | B36: First Batch (80 issues) | C36: =G30+G14 -> 30 | D36: =H30+H14 -> 50 | E36: =J30+J14 -> 9 | F36: =K30+K14 -> 10 | G36: =L30+L14 -> 19 | H36: 11 | I36: 4
A37: 2 | B37: Second Batch (70 issues) | C37: =N30+N14 -> 39 | D37: =O30+O14 -> 31 | E37: =Q30+Q14 -> 1 | F37: =R30+R14 -> 3 | G37: =S30+S14 -> 4 | H37: 0 | I37: 1
A38: 3 | B38: Third Batch (50 issues) | C38: =U30+U14 -> 37 | D38: =V30+V14 -> 13 | E38: =X30+X14 -> 14 | F38: =Y30+Y14 -> 6 | G38: =Z30+Z14 -> 20 | H38: 10 | I38: 1
A39: 4 | B39: Fourth Batch (25 issues) | C39: =AB30+AB14 -> 0 | D39: =AC30+AC14 -> 25 | E39: =AE30+AE14 -> 0 | F39: =AF30+AF14 -> 2 | G39: =AG30+AG14 -> 2 | H39: 0 | I39: 0
B40: TOTAL | C40: =SUM(C36:C39) -> 106 | D40: =SUM(D36:D39) -> 119 | E40: =SUM(E36:E39) -> 24 | F40: =SUM(F36:F39) -> 21 | G40: =SUM(G36:G39) -> 45 | H40: =SUM(H36:H39) -> 21 | I40: =SUM(I36:I39) -> 6
A44: Programming Language Distribution
A46: No | B46: Batch | C46: Total Issues (Python) | D46: Total F2P (Python) | E46: Total Issues (Typescript) | F46: Total F2P (Typescript) | G46: Total Issues (Rust) | H46: Total F2P (Rust)
A47: 1 | B47: First Batch (80 issues) | C47: 73 | D47: 19 | E47: 7 | F47: 0 | G47: 0 | H47: 0
A48: 2 | B48: Second Batch (70 issues) | C48: 53 | D48: 4 | E48: 8 | F48: 0 | G48: 9 | H48: 0
A49: 3 | B49: Third Batch (50 issues) | C49: 50 | D49: 20 | E49: 0 | F49: 0 | G49: 0 | H49: 0
...

Sheet Agent Distribution - Deepseek
A1: AGENT FRAMEWORKS
I2: Deepseek-v3.2
